Workbook
Name \A: #REF!
Name \A: #REF!
Name \C: #REF!
Name \C: #REF!
Name \F: #REF!
Name \F: #REF!
Name \G: #REF!
Name \G: #REF!
Name \p: #REF!
Name \p: #REF!
Name \Q: #REF!
Name \Q: #REF!
Name \Z: #REF!
Name \Z: #REF!
Name _?: #REF!
Name _?: #REF!
Name __: #REF!
Name __: #REF!
Name __?: #REF!
Name __?: #REF!
Name ___?: #REF!
Name ___?: #REF!
Name ____?: #REF!
Name ____?: #REF!
Name _____?: #REF!
Name _____?: #REF!
Name ______?: #REF!
Name ______?: #REF!
Name _______?: #REF!
Name _______?: #REF!
Name ________?: #REF!
Name ________?: #REF!
Name _________?: #REF!
Name _________?: #REF!
Name __________?: #REF!
Name __________?: #REF!
Name ____________________MAX61: #REF!
Name ____________________MAX61: #REF!
Name ___________________acv456: #N/A
Name ___________________MAX61: #REF!
Name ___________________MAX61: #REF!
Name __________________acv456: #N/A
Name __________________MAX61: #REF!
Name __________________MAX61: #REF!
Name _________________acv456: #N/A
Name _________________MAX61: #REF!
Name _________________MAX61: #REF!
Name ________________acv456: #N/A
Name ________________awe122: #REF!
Name ________________awe122: #REF!
Name ________________MAX61: #REF!
Name ________________MAX61: #REF!
Name _______________acv456: #REF!
Name _______________acv456: #REF!
Name _______________acv456: #REF!
Name _______________acv456: #REF!
Name _______________acv456: #REF!
Name _______________acv456: #REF!
Name _______________acv456: #REF!
Name _______________acv456: #REF!

Sheet Capacity
A1: SUMMARY OF TREATMENT CAPACITY
A2: BASED ON WEEKLY PRODUCTION, UNSCHEDULE ORDERS & RCCP
B4: CURRENT WEEK | V4: SEPT | Y4: OCTOBER | AN4: NOVEMBER | AQ4: =Embroidery!#REF! -> #REF! | AT4: =Embroidery!#REF! -> #REF! | AW4: =Embroidery!#REF! -> #REF! | AZ4: DECEMBER | BL4: JANUARY | CA4: FEBRUARY | CM4: MARCH
J5: ='Screen Printing'!J90 -> W. PROD 36 | M5: ='Screen Printing'!M90 -> W. PROD 37 | P5: ='Screen Printing'!P90 -> W. PROD 38 | S5: ='Screen Printing'!S90 -> W. PROD 39 | V5: W39 | Y5: W40 | AB5: W41 | AE5: W42 | AH5: W43 | AK5: W44 | AN5: W45 | AQ5: W46 | AT5: W47 | AW5: W48 | AZ5: W49 | BC5: W50 | BF5: W51 | BI5: W52 | BL5: W1 | BO5: W2 | BR5: W3 | BU5: W4 | BX5: W5 | CA5: W6 | CD5: W7 | CG5: W8 | CJ5: W9 | CM5: W10 | CP5: W11 | CS5: W12 | CV5: W13
A6: SCREEN PRINTING | C6: TOTAL MEJA SABLON | D6: 31 | G6: BALANCE/WEEK | J6: ='Screen Printing'!J91 -> 0 | M6: ='Screen Printing'!M91 -> 12473 | P6: ='Screen Printing'!P91 -> 43498 | S6: ='Screen Printing'!S91 -> 103641 | V6: {=INDEX('Screen Printing'!$V91:$ZZ91,1,1+INT((COLUMN()-COLUMN($V$112))/3)*4)} -> 159612 | Y6: {=INDEX('Screen Printing'!$V91:$ZZ91,1,1+INT((COLUMN()-COLUMN($V$112))/3)*4)} -> 115413 | AB6: {=INDEX('Screen Printing'!$V91:$ZZ91,1,1+INT((COLUMN()-COLUMN($V$112))/3)*4)} -> 216030 | AE6: {=INDEX('Screen Printing'!$V91:$ZZ91,1,1+INT((COLUMN()-COLUMN($V$112))/3)*4)} -> 213024 | AH6: {=INDEX('Screen Printing'!$V91:$ZZ91,1,1+INT((COLUMN()-COLUMN($V$112))/3)*4)} -> 148344 | AK6: {=INDEX('Screen Printing'!$V91:$ZZ91,1,1+INT((COLUMN()-COLUMN($V$112))/3)*4)} -> 57612 | AN6: ='Screen Printing'!BI91 -> 257746.5 | AQ6: ='Screen Printing'!BM91 -> 39700.5 | AT6: =INDEX('Screen Printing'!$BY91:$ZZ91,1,1+INT((COLUMN()-COLUMN($AT$100))/3)*4) -> 182037 | AW6: =INDEX('Screen Printing'!$BY91:$ZZ91,1,1+INT((COLUMN()-COLUMN($AT$100))/3)*4) -> 210093 | AZ6: =INDEX('Screen Printing'!$BY91:$ZZ91,1,1+INT((COLUMN()-COLUMN($AT$100))/3)*4) -> 171018 | BC6: =INDEX('Screen Printing'!$BY91:$ZZ91,1,1+INT((COLUMN()-COLUMN($AT$100))/3)*4) -> 203730 | BF6: =INDEX('Screen Printing'!$BY91:$ZZ91,1,1+INT((COLUMN()-COLUMN($AT$100))/3)*4) -> 136116 | BI6: =INDEX('Screen Printing'!$BY91:$ZZ91,1,1+INT((COLUMN()-COLUMN($AT$100))/3)*4) -> 210153.6 | BL6: =INDEX('Screen Printing'!$BY91:$ZZ91,1,1+INT((COLUMN()-COLUMN($AT$100))/3)*4) -> 253099.8 | BO6: =INDEX('Screen Printing'!$BY91:$ZZ91,1,1+INT((COLUMN()-COLUMN($AT$100))/3)*4) -> 178735.8 | BR6: =INDEX('Screen Printing'!$BY91:$ZZ91,1,1+INT((COLUMN()-COLUMN($AT$100))/3)*4) -> 173695.8 | BU6: =INDEX('Screen Printing'!$BY91:$ZZ91,1,1+INT((COLUMN()-COLUMN($AT$100))/3)*4) -> 176923.8 | BX6: =INDEX('Screen Printing'!$BY91:$ZZ91,1,1+INT((COLUMN()-COLUMN($AT$100))/3)*4) -> 229123.2 | CA6: =INDEX('Screen Printing'!$BY91:$ZZ91,1,1+INT((COLUMN()-COLUMN($AT$100))/3)*4) -> 206524.5 | CD6: =INDEX('Screen Printing'!$BY91:$ZZ91,1,1+INT((COLUMN()-COLUMN($AT$100))/3)*4) -> 205510.5 | CG6: =INDEX('Screen Printing'!$BY91:$ZZ91,1,1+INT((COLUMN()-COLUMN($AT$100))/3)*4) -> 201760.5 | CJ6: =INDEX('Screen Printing'!$BY91:$ZZ91,1,1+INT((COLUMN()-COLUMN($AT$100))/3)*4) -> 159706.5 | CM6: =INDEX('Screen Printing'!$BY91:$ZZ91,1,1+INT((COLUMN()-COLUMN($AT$100))/3)*4) -> 252373.5 | CP6: =INDEX('Screen Printing'!$BY91:$ZZ91,1,1+INT((COLUMN()-COLUMN($AT$100))/3)*4) -> 253585.5 | CS6: =INDEX('Screen Printing'!$BY91:$ZZ91,1,1+INT((COLUMN()-COLUMN($AT$100))/3)*4) -> 252757.5 | CV6: =INDEX('Screen Printing'!$BY91:$ZZ91,1,1+INT((COLUMN()-COLUMN($AT$100))/3)*4) -> 237520.5
C7: ADD (25 M) | D7: 10 | G7: SHIFT | J7: ='Screen Printing'!J92 -> 0 | M7: ='Screen Printing'!M92 -> 0 | P7: ='Screen Printing'!P92 -> 0 | S7: ='Screen Printing'!S92 -> 10.99564 | V7: 3 | Y7: 3 | AB7: 3 | AE7: 3 | AH7: 3 | AK7: 3 | AN7: 3 | AQ7: 3 | AT7: 3 | AW7: 3 | AZ7: 3 | BC7: 3 | BF7: 3 | BI7: 3 | BL7: 3 | BO7: 3 | BR7: 3 | BU7: 3 | BX7: 3 | CA7: 3 | CD7: 3 | CG7: 3 | CJ7: 3 | CM7: 3 | CP7: 3 | CS7: 3 | CV7: 3
C8: TOTAL MEJA SABLON | D8: =SUM(D6:D7) -> 41 | G8: JAM KERJA | J8: ='Screen Printing'!J93 -> 31 | M8: ='Screen Printing'!M93 -> 31 | P8: ='Screen Printing'!P93 -> 31 | S8: ='Screen Printing'!S93 -> 31 | V8: 21 | Y8: 21 | AB8: 21 | AE8: 21 | AH8: 21 | AK8: 21 | AN8: 21 | AQ8: 21 | AT8: 21 | AW8: 21 | AZ8: 21 | BC8: 21 | BF8: 21 | BI8: 21 | BL8: 21 | BO8: 21 | BR8: 21 | BU8: 21 | BX8: 21 | CA8: 21 | CD8: 21 | CG8: 21 | CJ8: 21 | CM8: 21 | CP8: 21 | CS8: 21 | CV8: 21
G9: +/- | J9: ='Screen Printing'!J94 -> 31 | M9: ='Screen Printing'!M94 -> 31 | P9: ='Screen Printing'!P94 -> 31 | S9: ='Screen Printing'!S94 -> 20.00436 | V9: {=INDEX('Screen Printing'!$V94:$ZZ94,1,1+INT((COLUMN()-COLUMN($V$112))/3)*4)} -> -3.5 | Y9: {=INDEX('Screen Printing'!$V94:$ZZ94,1,1+INT((COLUMN()-COLUMN($V$112))/3)*4)} -> 4.5 | AB9: {=INDEX('Screen Printing'!$V94:$ZZ94,1,1+INT((COLUMN()-COLUMN($V$112))/3)*4)} -> -2 | AE9: {=INDEX('Screen Printing'!$V94:$ZZ94,1,1+INT((COLUMN()-COLUMN($V$112))/3)*4)} -> -2 | AH9: {=INDEX('Screen Printing'!$V94:$ZZ94,1,1+INT((COLUMN()-COLUMN($V$112))/3)*4)} -> 6 | AK9: {=INDEX('Screen Printing'!$V94:$ZZ94,1,1+INT((COLUMN()-COLUMN($V$112))/3)*4)} -> 19 | AN9: ='Screen Printing'!BI94 -> -7 | AQ9: ='Screen Printing'!BM94 -> 19 | AT9: =INDEX('Screen Printing'!$BY94:$ZZ94,1,1+INT((COLUMN()-COLUMN($AT$100))/3)*4) -> 3.5 | AW9: =INDEX('Screen Printing'!$BY94:$ZZ94,1,1+INT((COLUMN()-COLUMN($AT$100))/3)*4) -> -1 | AZ9: =INDEX('Screen Printing'!$BY94:$ZZ94,1,1+INT((COLUMN()-COLUMN($AT$100))/3)*4) -> -2 | BC9: =INDEX('Screen Printing'!$BY94:$ZZ94,1,1+INT((COLUMN()-COLUMN($AT$100))/3)*4) -> 0.5 | BF9: =INDEX('Screen Printing'!$BY94:$ZZ94,1,1+INT((COLUMN()-COLUMN($AT$100))/3)*4) -> 4.5 | BI9: =INDEX('Screen Printing'!$BY94:$ZZ94,1,1+INT((COLUMN()-COLUMN($AT$100))/3)*4) -> -7.5 | BL9: =INDEX('Screen Printing'!$BY94:$ZZ94,1,1+INT((COLUMN()-COLUMN($AT$100))/3)*4) -> -9.5 | BO9: =INDEX('Screen Printing'!$BY94:$ZZ94,1,1+INT((COLUMN()-COLUMN($AT$100))/3)*4) -> 0.5 | BR9: =INDEX('Screen Printing'!$BY94:$ZZ94,1,1+INT((COLUMN()-COLUMN($AT$100))/3)*4) -> 3 | BU9: =INDEX('Screen Printing'!$BY94:$ZZ94,1,1+INT((COLUMN()-COLUMN($AT$100))/3)*4) -> 3 | BX9: =INDEX('Screen Printing'!$BY94:$ZZ94,1,1+INT((COLUMN()-COLUMN($AT$100))/3)*4) -> 2 | CA9: =INDEX('Screen Printing'!$BY94:$ZZ94,1,1+INT((COLUMN()-COLUMN($AT$100))/3)*4) -> -6.5 | CD9: =INDEX('Screen Printing'!$BY94:$ZZ94,1,1+INT((COLUMN()-COLUMN($AT$100))/3)*4) -> -2 | CG9: =INDEX('Screen Printing'!$BY94:$ZZ94,1,1+INT((COLUMN()-COLUMN($AT$100))/3)*4) -> 0.5 | CJ9: =INDEX('Screen Printing'!$BY94:$ZZ94,1,1+INT((COLUMN()-COLUMN($AT$100))/3)*4) -> 1 | CM9: =INDEX('Screen Printing'!$BY94:$ZZ94,1,1+INT((COLUMN()-COLUMN($AT$100))/3)*4) -> -4 | CP9: =INDEX('Screen Printing'!$BY94:$ZZ94,1,1+INT((COLUMN()-COLUMN($AT$100))/3)*4) -> -4.5 | CS9: =INDEX('Screen Printing'!$BY94:$ZZ94,1,1+INT((COLUMN()-COLUMN($AT$100))/3)*4) -> -12 | CV9: =INDEX('Screen Printing'!$BY94:$ZZ94,1,1+INT((COLUMN()-COLUMN($AT$100))/3)*4) -> -1
G10: AVERAGE | V10: =AVERAGE(V9) -> -3.5 | Y10: =AVERAGE(Y9:AM9) -> 5.1 | AB10: =SUM(AB6:AP6) -> 892756.5 | AN10: =AVERAGE(AN9:AY9) -> 3.625 | AQ10: =SUM(AQ6:BB6) -> 602848.5 | AZ10: =AVERAGE(AZ9:BK9) -> -1.125 | BC10: =SUM(BC6:BN6) -> 803099.4 | BL10: =AVERAGE(BL9:BZ9) -> -0.2 | BO10: =SUM(BO6:CC6) -> 965003.1 | CA10: =AVERAGE(CA9:CL9) -> -1.75 | CD10: =SUM(CD6:CO6) -> 819351 | CM10: =AVERAGE(CM9:CX9) -> -5.375 | CP10: =SUM(CP6:DA6) -> 743863.5
V13: SEPT | Y13: OCTOBER | AN13: NOVEMBER | AZ13: DECEMBER | BL13: JANUARY | CA13: FEBRUARY | CM13: MARCH
J14: =+#REF! -> #REF! | M14: ='Auto Print'!P22 -> 0 | P14: ='Auto Print'!S22 -> 2064 | S14: ='Auto Print'!V22 -> 3906 | V14: W39 | Y14: W40 | AB14: W41 | AE14: W42 | AH14: W43 | AK14: W44 | AN14: W45 | AQ14: W46 | AT14: W47 | AW14: W48 | AZ14: W49 | BC14: W50 | BF14: W51 | BI14: W52 | BL14: W1 | BO14: W2 | BR14: W3 | BU14: W4 | BX14: W5 | CA14: W6 | CD14: W7 | CG14: W8 | CJ14: W9 | CM14: W10 | CP14: W11 | CS14: W12 | CV14: W13
C15: TOTAL MESIN | D15: 1 | G15: BALANCE/WEEK | J15: =#REF! -> #REF! | M15: ='Auto Print'!P23 -> 0 | P15: ='Auto Print'!S23 -> 2064 | S15: ='Auto Print'!V23 -> 4782 | V15: ='Auto Print'!Y32 -> 33935 | Y15: ='Auto Print'!AB32 -> 13969 | AB15: ='Auto Print'!AE32 -> 46578 | AE15: ='Auto Print'!AH32 -> 43824 | AH15: ='Auto Print'!AK32 -> 26214 | AK15: ='Auto Print'!AN32 -> 0 | AN15: ='Auto Print'!AW32 -> 13317 | AQ15: ='Auto Print'!AZ32 -> 2715 | AT15: ='Auto Print'!BC32 -> 68733 | AW15: ='Auto Print'!BF32 -> 10071 | AZ15: ='Auto Print'!BI32 -> 31620 | BC15: ='Auto Print'!BL32 -> 34512 | BF15: ='Auto Print'!BO32 -> 26496 | BI15: ='Auto Print'!BR32 -> 52852.8 | BL15: ='Auto Print'!BU32 -> 16747.2 | BO15: ='Auto Print'!BX32 -> 9031.2 | BR15: ='Auto Print'!CA32 -> 8467.2 | BU15: ='Auto Print'!CD32 -> 11731.2 | BX15: ='Auto Print'!CG32 -> 31667.4 | CA15: ='Auto Print'!CJ32 -> 27861 | CD15: ='Auto Print'!CM32 -> 27861 | CG15: ='Auto Print'!CP32 -> 27861 | CJ15: ='Auto Print'!CS32 -> 23992.5 | CM15: ='Auto Print'!CV32 -> 55393.5 | CP15: ='Auto Print'!CY32 -> 55393.5 | CS15: ='Auto Print'!DB32 -> 55393.5 | CV15: ='Auto Print'!DE32 -> 38025
A16: AUTO PRINTING | C16: ADD (MESIN) | D16: 2 | G16: SHIFT | J16: =#REF! -> #REF! | M16: ='Auto Print'!P24 -> 0 | P16: ='Auto Print'!S24 -> 0 | S16: ='Auto Print'!V24 -> 0 | V16: 2 | Y16: 2 | AB16: 2 | AE16: 2 | AH16: 2 | AK16: 2 | AN16: 2 | AQ16: 2 | AT16: 2 | AW16: 2 | AZ16: 2 | BC16: 2 | BF16: 2 | BI16: 2 | BL16: 2 | BO16: 2 | BR16: 2 | BU16: 2 | BX16: 2 | CA16: 2 | CD16: 2 | CG16: 2 | CJ16: 2 | CM16: 2 | CP16: 2 | CS16: 2 | CV16: 2
C17: TOTAL | D17: 3 | G17: JAM KERJA | J17: =+$D$58 -> 0 | M17: ='Auto Print'!P25 -> 0 | P17: ='Auto Print'!S25 -> 2796 | S17: ='Auto Print'!V25 -> 4308 | V17: 20 | Y17: 20 | AB17: 20 | AE17: 20 | AH17: 20 | AK17: 20 | AN17: 20 | AQ17: 20 | AT17: 20 | AW17: 20 | AZ17: 20 | BC17: 20 | BF17: 20 | BI17: 20 | BL17: 20 | BO17: 20 | BR17: 20 | BU17: 20 | BX17: 20 | CA17: 20 | CD17: 20 | CG17: 20 | CJ17: 20 | CM17: 20 | CP17: 20 | CS17: 20 | CV17: 20
G18: +/- | J18: =J17-J16 -> #REF! | M18: =M17-M16 -> 0 | P18: =P17-P16 -> 2796 | S18: =S17-S16 -> 4308 | V18: ='Auto Print'!Y35 -> 0.084663772 | Y18: ='Auto Print'!AB35 -> 0.56222261 | AB18: ='Auto Print'!AE35 -> -0.22254856 | AE18: ='Auto Print'!AH35 -> -0.19083855 | AH18: ='Auto Print'!AK35 -> 0.23089895 | AK18: ='Auto Print'!AN35 -> 1 | AN18: ='Auto Print'!AW35 -> 0.56904207 | AQ18: ='Auto Print'!AZ35 -> 0.89810953 | AT18: ='Auto Print'!BC35 -> -1.4617371 | AW18: ='Auto Print'!BF35 -> 0.62204828 | AZ18: ='Auto Print'!BI35 -> -0.08268066 | BC18: ='Auto Print'!BL35 -> -0.19121371 | BF18: ='Auto Print'!BO35 -> 0.10961649 | BI18: ='Auto Print'!BR35 -> -1.2810849 | BL18: ='Auto Print'!BU35 -> 0.26425713 | BO18: ='Auto Print'!BX35 -> 0.68290641 | BR18: ='Auto Print'!CA35 -> 0.70407261 | BU18: ='Auto Print'!CD35 -> 0.58157888 | BX18: ='Auto Print'!CG35 -> -0.17706695 | CA18: ='Auto Print'!CJ35 -> -0.25230396 | CD18: ='Auto Print'!CM35 -> -0.03260151 | CG18: ='Auto Print'!CP35 -> -0.03260151 | CJ18: ='Auto Print'!CS35 -> 0.11473509 | CM18: ='Auto Print'!CV35 -> -0.93587429 | CP18: ='Auto Print'!CY35 -> -0.93587429 | CS18: ='Auto Print'!DB35 -> -1.3477624 | CV18: ='Auto Print'!DE35 -> -0.27437354
G19: AVERAGE | V19: =AVERAGE(V18) -> 0.084663772 | Y19: =AVERAGE(Y18:AM18) -> 0.27594689 | AB19: =SUM(AB15:AP15) -> 129933 | AN19: =AVERAGE(AN18:AY18) -> 0.15686569 | AQ19: =SUM(AQ15:BB15) -> 113139 | AZ19: =AVERAGE(AZ18:BK18) -> -0.3613407 | BC19: =SUM(BC15:BN15) -> 130608 | BL19: =AVERAGE(BL18:BZ18) -> 0.41114962 | BO19: =SUM(BO15:CC15) -> 88758 | CA19: =AVERAGE(CA18:CL18) -> -0.050692973 | CD19: =SUM(CD15:CO15) -> 135108 | CM19: =AVERAGE(CM18:CX18) -> -0.87347114 | CP19: =SUM(CP15:DA15) -> 148812
V22: SEPT | Y22: OCTOBER | AN22: NOVEMBER | AZ22: DECEMBER | BL22: JANUARY | CA22: FEBRUARY | CM22: MARCH
J23: =+#REF! -> #REF! | M23: ='Auto Print'!P31 -> WEEK PRODUKSI 37 | P23: ='Auto Print'!S31 -> WEEK PRODUKSI 38 | S23: ='Auto Print'!V31 -> WEEK PRODUKSI 39 | V23: W39 | Y23: W40 | AB23: W41 | AE23: W42 | AH23: W43 | AK23: W44 | AN23: W45 | AQ23: W46 | AT23: W47 | AW23: W48 | AZ23: W49 | BC23: W50 | BF23: W51 | BI23: W52 | BL23: W1 | BO23: W2 | BR23: W3 | BU23: W4 | BX23: W5 | CA23: W6 | CD23: W7 | CG23: W8 | CJ23: W9 | CM23: W10 | CP23: W11 | CS23: W12 | CV23: W13
C24: TOTAL MESIN | D24: 1 | G24: BALANCE/WEEK | J24: =K9 -> 0 | M24: ='Auto Print'!P32 -> 0 | P24: ='Auto Print'!S32 -> 7575 | S24: ='Auto Print'!V32 -> 22052 | V24: ='Auto Print'!Y70 -> 33935 | Y24: ='Auto Print'!AB70 -> 13969 | AB24: ='Auto Print'!AE70 -> 46578 | AE24: ='Auto Print'!AH70 -> 43824 | AH24: ='Auto Print'!AK70 -> 26214 | AK24: ='Auto Print'!AN70 -> 0 | AN24: ='Auto Print'!AW70 -> 13317 | AQ24: ='Auto Print'!AZ70 -> 2715 | AT24: ='Auto Print'!BC70 -> 68733 | AW24: ='Auto Print'!BF70 -> 10071 | AZ24: ='Auto Print'!BI70 -> 31620 | BC24: ='Auto Print'!BL70 -> 34512 | BF24: ='Auto Print'!BO70 -> 26496 | BI24: ='Auto Print'!BR70 -> 52852.8 | BL24: ='Auto Print'!BU70 -> 16747.2 | BO24: ='Auto Print'!BX70 -> 9031.2 | BR24: ='Auto Print'!CA70 -> 8467.2 | BU24: ='Auto Print'!CD70 -> 11731.2 | BX24: ='Auto Print'!CG70 -> 31667.4 | CA24: ='Auto Print'!CJ70 -> 27861 | CD24: ='Auto Print'!CM70 -> 27861 | CG24: ='Auto Print'!CP70 -> 27861 | CJ24: ='Auto Print'!CS70 -> 23992.5 | CM24: ='Auto Print'!CV70 -> 55393.5 | CP24: ='Auto Print'!CY70 -> 55393.5 | CS24: ='Auto Print'!DB70 -> 55393.5 | CV24: ='Auto Print'!DE70 -> 38025
A25: AUTO CUTTING | C25: ADD (MESIN) | D25: 2 | G25: SHIFT | J25: =L9 -> 0 | M25: ='Auto Print'!P33 -> 0 | P25: ='Auto Print'!S33 -> 0 | S25: ='Auto Print'!V33 -> 0.61674332 | V25: 2 | Y25: 2 | AB25: 2 | AE25: 2 | AH25: 2 | AK25: 2 | AN25: 2 | AQ25: 2 | AT25: 2 | AW25: 2 | AZ25: 2 | BC25: 2 | BF25: 2 | BI25: 2 | BL25: 2 | BO25: 2 | BR25: 2 | BU25: 2 | BX25: 2 | CA25: 2 | CD25: 2 | CG25: 2 | CJ25: 2 | CM25: 2 | CP25: 2 | CS25: 2 | CV25: 2
C26: TOTAL | D26: 3 | G26: JAM KERJA | J26: =+$D$58 -> 0 | M26: ='Auto Print'!P34 -> 1 | P26: ='Auto Print'!S34 -> 1 | S26: ='Auto Print'!V34 -> 1 | V26: 20 | Y26: 20 | AB26: 20 | AE26: 20 | AH26: 20 | AK26: 20 | AN26: 20 | AQ26: 20 | AT26: 20 | AW26: 20 | AZ26: 20 | BC26: 20 | BF26: 20 | BI26: 20 | BL26: 20 | BO26: 20 | BR26: 20 | BU26: 20 | BX26: 20 | CA26: 20 | CD26: 20 | CG26: 20 | CJ26: 20 | CM26: 20 | CP26: 20 | CS26: 20 | CV26: 20
G27: +/- | J27: =J26-J25 -> 0 | M27: =M26-M25 -> 1 | P27: =P26-P25 -> 1 | S27: =S26-S25 -> 0.38325668 | V27: ='Auto Print'!Y73 -> 1.3076172 | Y27: ='Auto Print'!AB73 -> 1.7144149 | AB27: ='Auto Print'!AE73 -> 0.97635009 | AE27: ='Auto Print'!AH73 -> 1.0733557 | AH27: ='Auto Print'!AK73 -> 1.4369984 | AK27: ='Auto Print'!AN73 -> 2 | AN27: ='Auto Print'!AW73 -> 1.752621 | AQ27: ='Auto Print'!AZ73 -> 1.9495657 | AT27: ='Auto Print'!BC73 -> 0.72320323 | AW27: ='Auto Print'!BF73 -> 1.8129193 | AZ27: ='Auto Print'!BI73 -> 1.4126211 | BC27: ='Auto Print'!BL73 -> 1.3588988 | BF27: ='Auto Print'!BO73 -> 1.5078055 | BI27: ='Auto Print'!BR73 -> 0.63713413 | BL27: ='Auto Print'!BU73 -> 1.4505414 | BO27: ='Auto Print'!BX73 -> 1.6902715 | BR27: ='Auto Print'!CA73 -> 1.7007484 | BU27: ='Auto Print'!CD73 -> 1.6401158 | BX27: ='Auto Print'!CG73 -> 0.18856829 | CA27: ='Auto Print'!CJ73 -> -0.11108999 | CD27: ='Auto Print'!CM73 -> 0.25927667 | CG27: ='Auto Print'!CP73 -> 0.25927667 | CJ27: ='Auto Print'!CS73 -> 0.55394986 | CM27: ='Auto Print'!CV73 -> -0.02936085 | CP27: ='Auto Print'!CY73 -> -0.02936085 | CS27: ='Auto Print'!DB73 -> -0.46113975 | CV27: ='Auto Print'!DE73 -> 1.2936407
G28: AVERAGE | V28: =AVERAGE(V27) -> 1.3076172 | Y28: =AVERAGE(Y27:AM27) -> 1.4402238 | AB28: =SUM(AB24:AP24) -> 129933 | AN28: =AVERAGE(AN27:AY27) -> 1.5595773 | AQ28: =SUM(AQ24:BB24) -> 113139 | AZ28: =AVERAGE(AZ27:BK27) -> 1.2291149 | BC28: =SUM(BC24:BN24) -> 130608 | BL28: =AVERAGE(BL27:BZ27) -> 1.3340491 | BO28: =SUM(BO24:CC24) -> 88758 | CA28: =AVERAGE(CA27:CL27) -> 0.2403533 | CD28: =SUM(CD24:CO24) -> 135108 | CM28: =AVERAGE(CM27:CX27) -> 0.1934448 | CP28: =SUM(CP24:DA24) -> 148812
V31: SEPT | Y31: OCTOBER | AN31: NOVEMBER | AZ31: DECEMBER | BL31: JANUARY | CA31: FEBRUARY | CM31: MARCH
J32: =+#REF! -> #REF! | M32: =Emboss!P61 -> WEEK PRODUKSI 37 | P32: =Emboss!S61 -> WEEK PRODUKSI 38 | S32: =Emboss!V61 -> WEEK PRODUKSI 39 | V32: W39 | Y32: W40 | AB32: W41 | AE32: W42 | AH32: W43 | AK32: W44 | AN32: W45 | AQ32: W46 | AT32: W47 | AW32: W48 | AZ32: W49 | BC32: W50 | BF32: W51 | BI32: W52 | BL32: W1 | BO32: W2 | BR32: W3 | BU32: W4 | BX32: W5 | CA32: W6 | CD32: W7 | CG32: W8 | CJ32: W9 | CM32: W10 | CP32: W11 | CS32: W12 | CV32: W13
G33: BALANCE/WEEK | J33: =K$89 -> 0 | M33: =Emboss!P62 -> 702 | P33: =Emboss!S62 -> 14086 | S33: =Emboss!V62 -> 90290 | V33: =Summary!V33 -> 106700 | Y33: =Summary!Y33 -> 90332 | AB33: =Summary!AB33 -> 165918 | AE33: =Summary!AE33 -> 128246 | AH33: =Summary!AH33 -> 140064 | AK33: =Summary!AK33 -> 32490 | AN33: =Summary!AN33 -> 19800 | AQ33: =Summary!AQ33 -> 53817 | AT33: =Summary!AT33 -> 6813 | AW33: =Summary!AW33 -> 34017 | AZ33: =Summary!AZ33 -> 74365.5 | BC33: =Summary!BC33 -> 83155.5 | BF33: =Summary!BF33 -> 63523.5 | BI33: =Summary!BI33 -> 117162.7 | BL33: =Summary!BL33 -> 40788.4 | BO33: =Summary!BO33 -> 25356.4 | BR33: =Summary!BR33 -> 24228.4 | BU33: =Summary!BU33 -> 30756.4 | BX33: =Summary!BX33 -> 87278.2 | CA33: =Summary!CA33 -> 81371.5 | CD33: =Summary!CD33 -> 84143.5 | CG33: =Summary!CG33 -> 79643.5 | CJ33: =Summary!CJ33 -> 64305 | CM33: =Summary!CM33 -> 127072.5 | CP33: =Summary!CP33 -> 127072.5 | CS33: =Summary!CS33 -> 127072.5 | CV33: =Summary!CV33 -> 82362
A34: EMBOSS | C34: TOTAL MESIN | D34: 22 | G34: SHIFT | J34: =L$89 -> 0 | M34: =Emboss!P63 -> 0 | P34: =Emboss!S63 -> 0 | S34: =Emboss!V63 -> 12.53807 | V34: 2 | Y34: 2 | AB34: 2 | AE34: 2 | AH34: 2 | AK34: 2 | AN34: 2 | AQ34: 2 | AT34: 2 | AW34: 2 | AZ34: 2 | BC34: 2 | BF34: 2 | BI34: 2 | BL34: 2 | BO34: 2 | BR34: 2 | BU34: 2 | BX34: 2 | CA34: 2 | CD34: 2 | CG34: 2 | CJ34: 2 | CM34: 2 | CP34: 2 | CS34: 2 | CV34: 2
C35: ADD 01/12 | D35: 10 | G35: JAM KERJA | J35: 22 | M35: =Emboss!P64 -> 22 | P35: =Emboss!S64 -> 22 | S35: =Emboss!V64 -> 22 | V35: 18 | Y35: 18 | AB35: 18 | AE35: 18 | AH35: 18 | AK35: 18 | AN35: 18 | AQ35: 18 | AT35: 18 | AW35: 18 | AZ35: 18 | BC35: 18 | BF35: 18 | BI35: 18 | BL35: 18 | BO35: 18 | BR35: 18 | BU35: 18 | BX35: 18 | CA35: 18 | CD35: 18 | CG35: 18 | CJ35: 18 | CM35: 18 | CP35: 18 | CS35: 18 | CV35: 18
C36: TOTAL MESIN | D36: =SUM(D34:D35) -> 32 | G36: +/- | J36: =J35-J34 -> 22 | M36: =Emboss!P65 -> 22 | P36: =Emboss!S65 -> 22 | S36: =Emboss!V65 -> 9.46193 | V36: =Summary!V36 -> 7.1430359 | Y36: =Summary!Y36 -> 9.4266414 | AB36: =Summary!AB36 -> -0.851502 | AE36: =Summary!AE36 -> 3.1840382 | AH36: =Summary!AH36 -> -1.0660166 | AK36: =Summary!AK36 -> 16.457644 | AN36: =Summary!AN36 -> 18.836538 | AQ36: =Summary!AQ36 -> 14.107853 | AT36: =Summary!AT36 -> 21.148759 | AW36: =Summary!AW36 -> 17.271314 | AZ36: =Summary!AZ36 -> 22.381974 | BC36: =Summary!BC36 -> 21.194174 | BF36: =Summary!BF36 -> 23.76722 | BI36: =Summary!BI36 -> 14.175321 | BL36: =Summary!BL36 -> 26.280682 | BO36: =Summary!BO36 -> 29.270574 | BR36: =Summary!BR36 -> 29.413111 | BU36: =Summary!BU36 -> 28.58822 | BX36: =Summary!BX36 -> 25.521839 | CA36: =Summary!CA36 -> 24.892653 | CD36: =Summary!CD36 -> 25.742014 | CG36: =Summary!CG36 -> 26.460982 | CJ36: =Summary!CJ36 -> 26.558887 | CM36: =Summary!CM36 -> 18.117962 | CP36: =Summary!CP36 -> 18.117962 | CS36: =Summary!CS36 -> 15.033064 | CV36: =Summary!CV36 -> 21.105241
G37: AVERAGE | V37: =AVERAGE(V36) -> 7.1430359 | Y37: =AVERAGE(Y36:AM36) -> 5.430161 | AB37: =SUM(AB33:AP33) -> 486518 | AN37: =AVERAGE(AN36:AY36) -> 17.841116 | AQ37: =SUM(AQ33:BB33) -> 169012.5 | AZ37: =AVERAGE(AZ36:BK36) -> 20.379672 | BC37: =SUM(BC33:BN33) -> 304630.1 | BL37: =AVERAGE(BL36:BZ36) -> 27.814885 | BO37: =SUM(BO33:CC33) -> 248990.9 | CA37: =AVERAGE(CA36:CL36) -> 25.913634 | CD37: =SUM(CD33:CO33) -> 355164.5 | CM37: =AVERAGE(CM36:CX36) -> 18.093557 | CP37: =SUM(CP33:DA33) -> 336507
V40: SEPT | Y40: OCTOBER | AN40: NOVEMBER | AZ40: DECEMBER | BL40: JANUARY | CA40: FEBRUARY | CM40: MARCH
J41: =+#REF! -> #REF! | M41: ='Cut Press'!P32 -> WEEK PRODUKSI 37 | P41: ='Cut Press'!S32 -> WEEK PRODUKSI 38 | S41: ='Cut Press'!V32 -> WEEK PRODUKSI 39 | V41: W39 | Y41: W40 | AB41: W41 | AE41: W42 | AH41: W43 | AK41: W44 | AN41: W45 | AQ41: W46 | AT41: W47 | AW41: W48 | AZ41: W49 | BC41: W50 | BF41: W51 | BI41: W52 | BL41: W1 | BO41: W2 | BR41: W3 | BU41: W4 | BX41: W5 | CA41: W6 | CD41: W7 | CG41: W8 | CJ41: W9 | CM41: W10 | CP41: W11 | CS41: W12 | CV41: W13
G42: BALANCE/WEEK | J42: =K$62 -> 0 | M42: ='Cut Press'!P34 -> 0 | P42: ='Cut Press'!S34 -> 9462 | S42: ='Cut Press'!V34 -> 12324 | V42: ='Cut Press'!Y34 -> 21786 | Y42: ='Cut Press'!AB34 -> 36030 | AB42: ='Cut Press'!AE34 -> 68376 | AE42: ='Cut Press'!AH34 -> 55860 | AH42: ='Cut Press'!AK34 -> 24456 | AK42: ='Cut Press'!AN34 -> 1362 | AN42: ='Cut Press'!AW34 -> 32293.5 | AQ42: ='Cut Press'!BC34 -> 4072.5 | AT42: ='Cut Press'!BF34 -> 110947.5 | AW42: ='Cut Press'!BI34 -> 26380.5 | AZ42: ='Cut Press'!BL34 -> 56629.5 | BC42: ='Cut Press'!BO34 -> 59863.5 | BF42: ='Cut Press'!BR34 -> 44239.5 | BI42: ='Cut Press'!BU34 -> 80077.5 | BL42: ='Cut Press'!BX34 -> 25533.6 | BO42: ='Cut Press'!CA34 -> 9849.6 | BR42: ='Cut Press'!CD34 -> 9003.6 | BU42: ='Cut Press'!CG34 -> 13899.6 | BX42: ='Cut Press'!CJ34 -> 15645.6 | CA42: ='Cut Press'!CM34 -> 10498.5 | CD42: ='Cut Press'!CP34 -> 10960.5 | CG42: ='Cut Press'!CS34 -> 10210.5 | CJ42: ='Cut Press'!CV34 -> 10210.5 | CM42: ='Cut Press'!CY34 -> 63454.5 | CP42: ='Cut Press'!DB34 -> 63454.5 | CS42: ='Cut Press'!DE34 -> 63454.5 | CV42: ='Cut Press'!DH34 -> 63454.5
A43: CUTTING PRESS | C43: TOTAL HOLD | D43: 16 | G43: SHIFT | J43: =L$62 -> 0 | M43: ='Cut Press'!P35 -> 0 | P43: ='Cut Press'!S35 -> 0 | S43: ='Cut Press'!V35 -> 2.7151515 | V43: 1 | Y43: 1 | AB43: 1 | AE43: 1 | AH43: 1 | AK43: 1 | AN43: 1 | AQ43: 1 | AT43: 1 | AW43: 1 | AZ43: 1 | BC43: 1 | BF43: 1 | BI43: 1 | BL43: 1 | BO43: 1 | BR43: 1 | BU43: 1 | BX43: 1 | CA43: 1 | CD43: 1 | CG43: 1 | CJ43: 1 | CM43: 1 | CP43: 1 | CS43: 1 | CV43: 1
A44: (Model 880,1906) | C44: ADD (2 MC) | D44: 16 | G44: JAM KERJA | J44: 8 | M44: ='Cut Press'!P36 -> 8 | P44: ='Cut Press'!S36 -> 8 | S44: ='Cut Press'!V36 -> 8 | V44: 7 | Y44: 7 | AB44: 7 | AE44: 7 | AH44: 7 | AK44: 7 | AN44: 7 | AQ44: 7 | AT44: 7 | AW44: 7 | AZ44: 7 | BC44: 7 | BF44: 7 | BI44: 7 | BL44: 7 | BO44: 7 | BR44: 7 | BU44: 7 | BX44: 7 | CA44: 7 | CD44: 7 | CG44: 7 | CJ44: 7 | CM44: 7 | CP44: 7 | CS44: 7 | CV44: 7
G45: +/- | J45: =J44-J43 -> 8 | M45: ='Cut Press'!P37 -> 8 | P45: ='Cut Press'!S37 -> 8 | S45: ='Cut Press'!V37 -> 5.2848485 | V45: ='Cut Press'!Y37 -> 11.120346 | Y45: ='Cut Press'!AB37 -> 7.4955267 | AB45: ='Cut Press'!AE37 -> -2.0779221 | AE45: ='Cut Press'!AH37 -> 3.6640693 | AH45: ='Cut Press'!AK37 -> 9.6207792 | AK45: ='Cut Press'!AN37 -> 15.213853 | AN45: ='Cut Press'!AW37 -> 8.5168831 | AQ45: ='Cut Press'!BC37 -> 15.21645 | AT45: ='Cut Press'!BF37 -> -5.9212121 | AW45: ='Cut Press'!BI37 -> 15.254365 | AZ45: ='Cut Press'!BL37 -> 5.6289602 | BC45: ='Cut Press'!BO37 -> 4.4822511 | BF45: ='Cut Press'!BR37 -> 7.4883117 | BI45: ='Cut Press'!BU37 -> 0.59307359 | BL45: ='Cut Press'!BX37 -> -1.1695238 | BO45: ='Cut Press'!CA37 -> 14.104935 | BR45: ='Cut Press'!CD37 -> 14.267706 | BU45: ='Cut Press'!CG37 -> 13.325714 | BX45: ='Cut Press'!CJ37 -> 12.320847 | CA45: ='Cut Press'!CM37 -> 13.395767 | CD45: ='Cut Press'!CP37 -> 13.602597 | CG45: ='Cut Press'!CS37 -> 14.035498 | CJ45: ='Cut Press'!CV37 -> 14.035498 | CM45: ='Cut Press'!CY37 -> 3.791342 | CP45: ='Cut Press'!DB37 -> 3.791342 | CS45: ='Cut Press'!DE37 -> 1.0783069 | CV45: ='Cut Press'!DH37 -> 3.791342
G46: AVERAGE | V46: =AVERAGE(V45) -> 11.120346 | Y46: =AVERAGE(Y45:AM45) -> 6.7832612 | AB46: =SUM(AB42:AP42) -> 182347.5 | AN46: =AVERAGE(AN45:AY45) -> 8.2666216 | AQ46: =SUM(AQ42:BB42) -> 198030 | AZ46: =AVERAGE(AZ45:BK45) -> 4.5481491 | BC46: =SUM(BC42:BN42) -> 209714.1 | BL46: =AVERAGE(BL45:BZ45) -> 10.569936 | BO46: =SUM(BO42:CC42) -> 58896.9 | CA46: =AVERAGE(CA45:CL45) -> 13.76734 | CD46: =SUM(CD42:CO42) -> 94836 | CM46: =AVERAGE(CM45:CX45) -> 3.1130832 | CP46: =SUM(CP42:DA42) -> 190363.5
AQ49: DECEMBER | BC49: JANUARY | BR49: FEBRUARY | CD49: MARCH
J50: =+#REF! -> #REF! | M50: ='Cut Press'!P41 -> 0 | P50: ='Cut Press'!S41 -> 0 | S50: ='Cut Press'!V41 -> 0 | AQ50: W49 | AT50: W50 | AW50: W51 | AZ50: W52 | BC50: W1 | BF50: W2 | BI50: W3 | BL50: W4 | BO50: W5 | BR50: W6 | BU50: W7 | BX50: W8 | CA50: W9 | CD50: W10 | CG50: W11 | CJ50: W12 | CM50: W13
G51: BALANCE/WEEK | J51: =K$62 -> 0 | M51: ='Cut Press'!P43 -> 0 | P51: ='Cut Press'!S43 -> 0 | S51: ='Cut Press'!V43 -> 0 | AQ51: ='Cut Press'!CG43 -> 0 | AT51: ='Cut Press'!CJ43 -> 0 | AW51: ='Cut Press'!CM43 -> 0 | AZ51: =Summary!AE51 -> 2464.8 | BC51: =Summary!AH51 -> 2464.8 | BF51: =Summary!AK51 -> 2464.8 | BI51: =Summary!AN51 -> 2464.8 | BL51: =Summary!AQ51 -> 2464.8 | BO51: =Summary!AT51 -> 21903 | BR51: =Summary!AW51 -> 21903 | BU51: =Summary!AZ51 -> 21903 | BX51: =Summary!BC51 -> 21903 | CA51: =Summary!BF51 -> 35008.5 | CD51: =Summary!BI51 -> 35008.5 | CG51: =Summary!BL51 -> 35008.5 | CJ51: =Summary!BO51 -> 35008.5 | CM51: =Summary!BR51 -> 0
...

Sheet Summary
A1: SUMMARY OF TREATMENT CAPACITY
A2: BASED ON WEEKLY PRODUCTION, UNSCHEDULE ORDERS & RCCP
B4: CURRENT WEEK | V4: SEPT | Y4: OCTOBER | AN4: NOVEMBER | AQ4: =Embroidery!#REF! -> #REF! | AT4: =Embroidery!#REF! -> #REF! | AW4: =Embroidery!#REF! -> #REF! | AZ4: DECEMBER | BL4: JANUARY | CA4: FEBRUARY | CM4: MARCH
J5: ='Screen Printing'!J90 -> W. PROD 36 | M5: ='Screen Printing'!M90 -> W. PROD 37 | P5: ='Screen Printing'!P90 -> W. PROD 38 | S5: ='Screen Printing'!S90 -> W. PROD 39 | V5: W39 | Y5: W40 | AB5: W41 | AE5: W42 | AH5: W43 | AK5: W44 | AN5: W45 | AQ5: W46 | AT5: W47 | AW5: W48 | AZ5: W49 | BC5: W50 | BF5: W51 | BI5: W52 | BL5: W1 | BO5: W2 | BR5: W3 | BU5: W4 | BX5: W5 | CA5: W6 | CD5: W7 | CG5: W8 | CJ5: W9 | CM5: W10 | CP5: W11 | CS5: W12 | CV5: W13
A6: SCREEN PRINTING | C6: TOTAL MEJA SABLON | D6: 31 | G6: BALANCE/WEEK | J6: ='Screen Printing'!J91 -> 0 | M6: ='Screen Printing'!M91 -> 12473 | P6: ='Screen Printing'!P91 -> 43498 | S6: ='Screen Printing'!S91 -> 103641 | V6: {=INDEX('Screen Printing'!$V91:$ZZ91,1,1+INT((COLUMN()-COLUMN($V$112))/3)*4)} -> 159612 | Y6: {=INDEX('Screen Printing'!$V91:$ZZ91,1,1+INT((COLUMN()-COLUMN($V$112))/3)*4)} -> 115413 | AB6: {=INDEX('Screen Printing'!$V91:$ZZ91,1,1+INT((COLUMN()-COLUMN($V$112))/3)*4)} -> 216030 | AE6: {=INDEX('Screen Printing'!$V91:$ZZ91,1,1+INT((COLUMN()-COLUMN($V$112))/3)*4)} -> 213024 | AH6: {=INDEX('Screen Printing'!$V91:$ZZ91,1,1+INT((COLUMN()-COLUMN($V$112))/3)*4)} -> 148344 | AK6: {=INDEX('Screen Printing'!$V91:$ZZ91,1,1+INT((COLUMN()-COLUMN($V$112))/3)*4)} -> 57612 | AN6: ='Screen Printing'!BI91 -> 257746.5 | AQ6: ='Screen Printing'!BM91 -> 39700.5 | AT6: =INDEX('Screen Printing'!$BY91:$ZZ91,1,1+INT((COLUMN()-COLUMN($AT$100))/3)*4) -> 182037 | AW6: =INDEX('Screen Printing'!$BY91:$ZZ91,1,1+INT((COLUMN()-COLUMN($AT$100))/3)*4) -> 210093 | AZ6: =INDEX('Screen Printing'!$BY91:$ZZ91,1,1+INT((COLUMN()-COLUMN($AT$100))/3)*4) -> 171018 | BC6: =INDEX('Screen Printing'!$BY91:$ZZ91,1,1+INT((COLUMN()-COLUMN($AT$100))/3)*4) -> 203730 | BF6: =INDEX('Screen Printing'!$BY91:$ZZ91,1,1+INT((COLUMN()-COLUMN($AT$100))/3)*4) -> 136116 | BI6: =INDEX('Screen Printing'!$BY91:$ZZ91,1,1+INT((COLUMN()-COLUMN($AT$100))/3)*4) -> 210153.6 | BL6: =INDEX('Screen Printing'!$BY91:$ZZ91,1,1+INT((COLUMN()-COLUMN($AT$100))/3)*4) -> 253099.8 | BO6: =INDEX('Screen Printing'!$BY91:$ZZ91,1,1+INT((COLUMN()-COLUMN($AT$100))/3)*4) -> 178735.8 | BR6: =INDEX('Screen Printing'!$BY91:$ZZ91,1,1+INT((COLUMN()-COLUMN($AT$100))/3)*4) -> 173695.8 | BU6: =INDEX('Screen Printing'!$BY91:$ZZ91,1,1+INT((COLUMN()-COLUMN($AT$100))/3)*4) -> 176923.8 | BX6: =INDEX('Screen Printing'!$BY91:$ZZ91,1,1+INT((COLUMN()-COLUMN($AT$100))/3)*4) -> 229123.2 | CA6: =INDEX('Screen Printing'!$BY91:$ZZ91,1,1+INT((COLUMN()-COLUMN($AT$100))/3)*4) -> 206524.5 | CD6: =INDEX('Screen Printing'!$BY91:$ZZ91,1,1+INT((COLUMN()-COLUMN($AT$100))/3)*4) -> 205510.5 | CG6: =INDEX('Screen Printing'!$BY91:$ZZ91,1,1+INT((COLUMN()-COLUMN($AT$100))/3)*4) -> 201760.5 | CJ6: =INDEX('Screen Printing'!$BY91:$ZZ91,1,1+INT((COLUMN()-COLUMN($AT$100))/3)*4) -> 159706.5 | CM6: =INDEX('Screen Printing'!$BY91:$ZZ91,1,1+INT((COLUMN()-COLUMN($AT$100))/3)*4) -> 252373.5 | CP6: =INDEX('Screen Printing'!$BY91:$ZZ91,1,1+INT((COLUMN()-COLUMN($AT$100))/3)*4) -> 253585.5 | CS6: =INDEX('Screen Printing'!$BY91:$ZZ91,1,1+INT((COLUMN()-COLUMN($AT$100))/3)*4) -> 252757.5 | CV6: =INDEX('Screen Printing'!$BY91:$ZZ91,1,1+INT((COLUMN()-COLUMN($AT$100))/3)*4) -> 237520.5
C7: ADD (25 M) | D7: 10 | G7: KEBUTUHAN MEJA | J7: ='Screen Printing'!J92 -> 0 | M7: ='Screen Printing'!M92 -> 0 | P7: ='Screen Printing'!P92 -> 0 | S7: ='Screen Printing'!S92 -> 10.99564 | V7: {=INDEX('Screen Printing'!$V92:$ZZ92,1,1+INT((COLUMN()-COLUMN($V$112))/3)*4)} -> 34.5 | Y7: {=INDEX('Screen Printing'!$V92:$ZZ92,1,1+INT((COLUMN()-COLUMN($V$112))/3)*4)} -> 26.5 | AB7: {=INDEX('Screen Printing'!$V92:$ZZ92,1,1+INT((COLUMN()-COLUMN($V$112))/3)*4)} -> 33 | AE7: {=INDEX('Screen Printing'!$V92:$ZZ92,1,1+INT((COLUMN()-COLUMN($V$112))/3)*4)} -> 33 | AH7: {=INDEX('Screen Printing'!$V92:$ZZ92,1,1+INT((COLUMN()-COLUMN($V$112))/3)*4)} -> 25 | AK7: {=INDEX('Screen Printing'!$V92:$ZZ92,1,1+INT((COLUMN()-COLUMN($V$112))/3)*4)} -> 12 | AN7: ='Screen Printing'!BI92 -> 38 | AQ7: ='Screen Printing'!BM92 -> 12 | AT7: =INDEX('Screen Printing'!$BY92:$ZZ92,1,1+INT((COLUMN()-COLUMN($AT$100))/3)*4) -> 27.5 | AW7: =INDEX('Screen Printing'!$BY92:$ZZ92,1,1+INT((COLUMN()-COLUMN($AT$100))/3)*4) -> 32 | AZ7: =INDEX('Screen Printing'!$BY92:$ZZ92,1,1+INT((COLUMN()-COLUMN($AT$100))/3)*4) -> 33 | BC7: =INDEX('Screen Printing'!$BY92:$ZZ92,1,1+INT((COLUMN()-COLUMN($AT$100))/3)*4) -> 30.5 | BF7: =INDEX('Screen Printing'!$BY92:$ZZ92,1,1+INT((COLUMN()-COLUMN($AT$100))/3)*4) -> 26.5 | BI7: =INDEX('Screen Printing'!$BY92:$ZZ92,1,1+INT((COLUMN()-COLUMN($AT$100))/3)*4) -> 38.5 | BL7: =INDEX('Screen Printing'!$BY92:$ZZ92,1,1+INT((COLUMN()-COLUMN($AT$100))/3)*4) -> 40.5 | BO7: =INDEX('Screen Printing'!$BY92:$ZZ92,1,1+INT((COLUMN()-COLUMN($AT$100))/3)*4) -> 30.5 | BR7: =INDEX('Screen Printing'!$BY92:$ZZ92,1,1+INT((COLUMN()-COLUMN($AT$100))/3)*4) -> 28 | BU7: =INDEX('Screen Printing'!$BY92:$ZZ92,1,1+INT((COLUMN()-COLUMN($AT$100))/3)*4) -> 28 | BX7: =INDEX('Screen Printing'!$BY92:$ZZ92,1,1+INT((COLUMN()-COLUMN($AT$100))/3)*4) -> 29 | CA7: =INDEX('Screen Printing'!$BY92:$ZZ92,1,1+INT((COLUMN()-COLUMN($AT$100))/3)*4) -> 37.5 | CD7: =INDEX('Screen Printing'!$BY92:$ZZ92,1,1+INT((COLUMN()-COLUMN($AT$100))/3)*4) -> 33 | CG7: =INDEX('Screen Printing'!$BY92:$ZZ92,1,1+INT((COLUMN()-COLUMN($AT$100))/3)*4) -> 30.5 | CJ7: =INDEX('Screen Printing'!$BY92:$ZZ92,1,1+INT((COLUMN()-COLUMN($AT$100))/3)*4) -> 30 | CM7: =INDEX('Screen Printing'!$BY92:$ZZ92,1,1+INT((COLUMN()-COLUMN($AT$100))/3)*4) -> 35 | CP7: =INDEX('Screen Printing'!$BY92:$ZZ92,1,1+INT((COLUMN()-COLUMN($AT$100))/3)*4) -> 35.5 | CS7: =INDEX('Screen Printing'!$BY92:$ZZ92,1,1+INT((COLUMN()-COLUMN($AT$100))/3)*4) -> 43 | CV7: =INDEX('Screen Printing'!$BY92:$ZZ92,1,1+INT((COLUMN()-COLUMN($AT$100))/3)*4) -> 32
C8: TOTAL MEJA SABLON | D8: =SUM(D6:D7) -> 41 | G8: KAPASITAS MEJA | J8: ='Screen Printing'!J93 -> 31 | M8: ='Screen Printing'!M93 -> 31 | P8: ='Screen Printing'!P93 -> 31 | S8: ='Screen Printing'!S93 -> 31 | V8: {=INDEX('Screen Printing'!$V93:$ZZ93,1,1+INT((COLUMN()-COLUMN($V$112))/3)*4)} -> 31 | Y8: {=INDEX('Screen Printing'!$V93:$ZZ93,1,1+INT((COLUMN()-COLUMN($V$112))/3)*4)} -> 31 | AB8: {=INDEX('Screen Printing'!$V93:$ZZ93,1,1+INT((COLUMN()-COLUMN($V$112))/3)*4)} -> 31 | AE8: {=INDEX('Screen Printing'!$V93:$ZZ93,1,1+INT((COLUMN()-COLUMN($V$112))/3)*4)} -> 31 | AH8: {=INDEX('Screen Printing'!$V93:$ZZ93,1,1+INT((COLUMN()-COLUMN($V$112))/3)*4)} -> 31 | AK8: {=INDEX('Screen Printing'!$V93:$ZZ93,1,1+INT((COLUMN()-COLUMN($V$112))/3)*4)} -> 31 | AN8: ='Screen Printing'!BI93 -> 31 | AQ8: ='Screen Printing'!BM93 -> 31 | AT8: =INDEX('Screen Printing'!$BY93:$ZZ93,1,1+INT((COLUMN()-COLUMN($AT$100))/3)*4) -> 31 | AW8: =INDEX('Screen Printing'!$BY93:$ZZ93,1,1+INT((COLUMN()-COLUMN($AT$100))/3)*4) -> 31 | AZ8: =INDEX('Screen Printing'!$BY93:$ZZ93,1,1+INT((COLUMN()-COLUMN($AT$100))/3)*4) -> 31 | BC8: =INDEX('Screen Printing'!$BY93:$ZZ93,1,1+INT((COLUMN()-COLUMN($AT$100))/3)*4) -> 31 | BF8: =INDEX('Screen Printing'!$BY93:$ZZ93,1,1+INT((COLUMN()-COLUMN($AT$100))/3)*4) -> 31 | BI8: =INDEX('Screen Printing'!$BY93:$ZZ93,1,1+INT((COLUMN()-COLUMN($AT$100))/3)*4) -> 31 | BL8: =INDEX('Screen Printing'!$BY93:$ZZ93,1,1+INT((COLUMN()-COLUMN($AT$100))/3)*4) -> 31 | BO8: =INDEX('Screen Printing'!$BY93:$ZZ93,1,1+INT((COLUMN()-COLUMN($AT$100))/3)*4) -> 31 | BR8: =INDEX('Screen Printing'!$BY93:$ZZ93,1,1+INT((COLUMN()-COLUMN($AT$100))/3)*4) -> 31 | BU8: =INDEX('Screen Printing'!$BY93:$ZZ93,1,1+INT((COLUMN()-COLUMN($AT$100))/3)*4) -> 31 | BX8: =INDEX('Screen Printing'!$BY93:$ZZ93,1,1+INT((COLUMN()-COLUMN($AT$100))/3)*4) -> 31 | CA8: =INDEX('Screen Printing'!$BY93:$ZZ93,1,1+INT((COLUMN()-COLUMN($AT$100))/3)*4) -> 31 | CD8: =INDEX('Screen Printing'!$BY93:$ZZ93,1,1+INT((COLUMN()-COLUMN($AT$100))/3)*4) -> 31 | CG8: =INDEX('Screen Printing'!$BY93:$ZZ93,1,1+INT((COLUMN()-COLUMN($AT$100))/3)*4) -> 31 | CJ8: =INDEX('Screen Printing'!$BY93:$ZZ93,1,1+INT((COLUMN()-COLUMN($AT$100))/3)*4) -> 31 | CM8: =INDEX('Screen Printing'!$BY93:$ZZ93,1,1+INT((COLUMN()-COLUMN($AT$100))/3)*4) -> 31 | CP8: =INDEX('Screen Printing'!$BY93:$ZZ93,1,1+INT((COLUMN()-COLUMN($AT$100))/3)*4) -> 31 | CS8: =INDEX('Screen Printing'!$BY93:$ZZ93,1,1+INT((COLUMN()-COLUMN($AT$100))/3)*4) -> 31 | CV8: =INDEX('Screen Printing'!$BY93:$ZZ93,1,1+INT((COLUMN()-COLUMN($AT$100))/3)*4) -> 31
G9: +/- | J9: ='Screen Printing'!J94 -> 31 | M9: ='Screen Printing'!M94 -> 31 | P9: ='Screen Printing'!P94 -> 31 | S9: ='Screen Printing'!S94 -> 20.00436 | V9: {=INDEX('Screen Printing'!$V94:$ZZ94,1,1+INT((COLUMN()-COLUMN($V$112))/3)*4)} -> -3.5 | Y9: {=INDEX('Screen Printing'!$V94:$ZZ94,1,1+INT((COLUMN()-COLUMN($V$112))/3)*4)} -> 4.5 | AB9: {=INDEX('Screen Printing'!$V94:$ZZ94,1,1+INT((COLUMN()-COLUMN($V$112))/3)*4)} -> -2 | AE9: {=INDEX('Screen Printing'!$V94:$ZZ94,1,1+INT((COLUMN()-COLUMN($V$112))/3)*4)} -> -2 | AH9: {=INDEX('Screen Printing'!$V94:$ZZ94,1,1+INT((COLUMN()-COLUMN($V$112))/3)*4)} -> 6 | AK9: {=INDEX('Screen Printing'!$V94:$ZZ94,1,1+INT((COLUMN()-COLUMN($V$112))/3)*4)} -> 19 | AN9: ='Screen Printing'!BI94 -> -7 | AQ9: ='Screen Printing'!BM94 -> 19 | AT9: =INDEX('Screen Printing'!$BY94:$ZZ94,1,1+INT((COLUMN()-COLUMN($AT$100))/3)*4) -> 3.5 | AW9: =INDEX('Screen Printing'!$BY94:$ZZ94,1,1+INT((COLUMN()-COLUMN($AT$100))/3)*4) -> -1 | AZ9: =INDEX('Screen Printing'!$BY94:$ZZ94,1,1+INT((COLUMN()-COLUMN($AT$100))/3)*4) -> -2 | BC9: =INDEX('Screen Printing'!$BY94:$ZZ94,1,1+INT((COLUMN()-COLUMN($AT$100))/3)*4) -> 0.5 | BF9: =INDEX('Screen Printing'!$BY94:$ZZ94,1,1+INT((COLUMN()-COLUMN($AT$100))/3)*4) -> 4.5 | BI9: =INDEX('Screen Printing'!$BY94:$ZZ94,1,1+INT((COLUMN()-COLUMN($AT$100))/3)*4) -> -7.5 | BL9: =INDEX('Screen Printing'!$BY94:$ZZ94,1,1+INT((COLUMN()-COLUMN($AT$100))/3)*4) -> -9.5 | BO9: =INDEX('Screen Printing'!$BY94:$ZZ94,1,1+INT((COLUMN()-COLUMN($AT$100))/3)*4) -> 0.5 | BR9: =INDEX('Screen Printing'!$BY94:$ZZ94,1,1+INT((COLUMN()-COLUMN($AT$100))/3)*4) -> 3 | BU9: =INDEX('Screen Printing'!$BY94:$ZZ94,1,1+INT((COLUMN()-COLUMN($AT$100))/3)*4) -> 3 | BX9: =INDEX('Screen Printing'!$BY94:$ZZ94,1,1+INT((COLUMN()-COLUMN($AT$100))/3)*4) -> 2 | CA9: =INDEX('Screen Printing'!$BY94:$ZZ94,1,1+INT((COLUMN()-COLUMN($AT$100))/3)*4) -> -6.5 | CD9: =INDEX('Screen Printing'!$BY94:$ZZ94,1,1+INT((COLUMN()-COLUMN($AT$100))/3)*4) -> -2 | CG9: =INDEX('Screen Printing'!$BY94:$ZZ94,1,1+INT((COLUMN()-COLUMN($AT$100))/3)*4) -> 0.5 | CJ9: =INDEX('Screen Printing'!$BY94:$ZZ94,1,1+INT((COLUMN()-COLUMN($AT$100))/3)*4) -> 1 | CM9: =INDEX('Screen Printing'!$BY94:$ZZ94,1,1+INT((COLUMN()-COLUMN($AT$100))/3)*4) -> -4 | CP9: =INDEX('Screen Printing'!$BY94:$ZZ94,1,1+INT((COLUMN()-COLUMN($AT$100))/3)*4) -> -4.5 | CS9: =INDEX('Screen Printing'!$BY94:$ZZ94,1,1+INT((COLUMN()-COLUMN($AT$100))/3)*4) -> -12 | CV9: =INDEX('Screen Printing'!$BY94:$ZZ94,1,1+INT((COLUMN()-COLUMN($AT$100))/3)*4) -> -1
G10: TOTAL BALANCE | V10: =SUM(V6) -> 159612 | Y10: =SUM(Y6:AM6) -> 750423 | AB10: =SUM(AB6:AP6) -> 892756.5 | AN10: =SUM(AN6:AY6) -> 689577 | AQ10: =SUM(AQ6:BB6) -> 602848.5 | AZ10: =SUM(AZ6:BK6) -> 721017.6 | BC10: =SUM(BC6:BN6) -> 803099.4 | BL10: =SUM(BL6:BZ6) -> 1011578.4 | BO10: =SUM(BO6:CC6) -> 965003.1 | CA10: =SUM(CA6:CL6) -> 773502 | CD10: =SUM(CD6:CO6) -> 819351 | CM10: =SUM(CM6:CX6) -> 996237 | CP10: =SUM(CP6:DA6) -> 743863.5
V13: SEPT | Y13: OCTOBER | AN13: NOVEMBER | AZ13: DECEMBER | BL13: JANUARY | CA13: FEBRUARY | CM13: MARCH
J14: =+#REF! -> #REF! | M14: ='Auto Print'!P22 -> 0 | P14: ='Auto Print'!S22 -> 2064 | S14: ='Auto Print'!V22 -> 3906 | V14: W39 | Y14: W40 | AB14: W41 | AE14: W42 | AH14: W43 | AK14: W44 | AN14: W45 | AQ14: W46 | AT14: W47 | AW14: W48 | AZ14: W49 | BC14: W50 | BF14: W51 | BI14: W52 | BL14: W1 | BO14: W2 | BR14: W3 | BU14: W4 | BX14: W5 | CA14: W6 | CD14: W7 | CG14: W8 | CJ14: W9 | CM14: W10 | CP14: W11 | CS14: W12 | CV14: W13
C15: TOTAL MESIN | D15: 1 | G15: BALANCE/WEEK | J15: =#REF! -> #REF! | M15: ='Auto Print'!P23 -> 0 | P15: ='Auto Print'!S23 -> 2064 | S15: ='Auto Print'!V23 -> 4782 | V15: ='Auto Print'!Y32 -> 33935 | Y15: ='Auto Print'!AB32 -> 13969 | AB15: ='Auto Print'!AE32 -> 46578 | AE15: ='Auto Print'!AH32 -> 43824 | AH15: ='Auto Print'!AK32 -> 26214 | AK15: ='Auto Print'!AN32 -> 0 | AN15: ='Auto Print'!AW32 -> 13317 | AQ15: ='Auto Print'!AZ32 -> 2715 | AT15: ='Auto Print'!BC32 -> 68733 | AW15: ='Auto Print'!BF32 -> 10071 | AZ15: ='Auto Print'!BI32 -> 31620 | BC15: ='Auto Print'!BL32 -> 34512 | BF15: ='Auto Print'!BO32 -> 26496 | BI15: ='Auto Print'!BR32 -> 52852.8 | BL15: ='Auto Print'!BU32 -> 16747.2 | BO15: ='Auto Print'!BX32 -> 9031.2 | BR15: ='Auto Print'!CA32 -> 8467.2 | BU15: ='Auto Print'!CD32 -> 11731.2 | BX15: ='Auto Print'!CG32 -> 31667.4 | CA15: ='Auto Print'!CJ32 -> 27861 | CD15: ='Auto Print'!CM32 -> 27861 | CG15: ='Auto Print'!CP32 -> 27861 | CJ15: ='Auto Print'!CS32 -> 23992.5 | CM15: ='Auto Print'!CV32 -> 55393.5 | CP15: ='Auto Print'!CY32 -> 55393.5 | CS15: ='Auto Print'!DB32 -> 55393.5 | CV15: ='Auto Print'!DE32 -> 38025
A16: AUTO PRINTING | C16: ADD (MESIN) | D16: 2 | G16: KEBUTUHAN MESIN | J16: =#REF! -> #REF! | M16: ='Auto Print'!P24 -> 0 | P16: ='Auto Print'!S24 -> 0 | S16: ='Auto Print'!V24 -> 0 | V16: ='Auto Print'!Y33 -> 0.91533623 | Y16: ='Auto Print'!AB33 -> 0.43777739 | AB16: ='Auto Print'!AE33 -> 1.2225486 | AE16: ='Auto Print'!AH33 -> 1.1908386 | AH16: ='Auto Print'!AK33 -> 0.76910105 | AK16: ='Auto Print'!AN33 -> 0 | AN16: ='Auto Print'!AW33 -> 0.43095793 | AQ16: ='Auto Print'!AZ33 -> 0.10189047 | AT16: ='Auto Print'!BC33 -> 2.4617371 | AW16: ='Auto Print'!BF33 -> 0.37795172 | AZ16: ='Auto Print'!BI33 -> 1.0826807 | BC16: ='Auto Print'!BL33 -> 1.1912137 | BF16: ='Auto Print'!BO33 -> 0.89038351 | BI16: ='Auto Print'!BR33 -> 2.2810849 | BL16: ='Auto Print'!BU33 -> 0.73574287 | BO16: ='Auto Print'!BX33 -> 0.31709359 | BR16: ='Auto Print'!CA33 -> 0.29592739 | BU16: ='Auto Print'!CD33 -> 0.41842112 | BX16: ='Auto Print'!CG33 -> 1.1770669 | CA16: ='Auto Print'!CJ33 -> 1.252304 | CD16: ='Auto Print'!CM33 -> 1.0326015 | CG16: ='Auto Print'!CP33 -> 1.0326015 | CJ16: ='Auto Print'!CS33 -> 0.88526491 | CM16: ='Auto Print'!CV33 -> 1.9358743 | CP16: ='Auto Print'!CY33 -> 1.9358743 | CS16: ='Auto Print'!DB33 -> 2.3477624 | CV16: ='Auto Print'!DE33 -> 1.2743735
C17: TOTAL | D17: 3 | G17: KAPASITAS MESIN | J17: =+$D$58 -> 0 | M17: ='Auto Print'!P25 -> 0 | P17: ='Auto Print'!S25 -> 2796 | S17: ='Auto Print'!V25 -> 4308 | V17: ='Auto Print'!Y34 -> 1 | Y17: ='Auto Print'!AB34 -> 1 | AB17: ='Auto Print'!AE34 -> 1 | AE17: ='Auto Print'!AH34 -> 1 | AH17: ='Auto Print'!AK34 -> 1 | AK17: ='Auto Print'!AN34 -> 1 | AN17: ='Auto Print'!AW34 -> 1 | AQ17: ='Auto Print'!AZ34 -> 1 | AT17: ='Auto Print'!BC34 -> 1 | AW17: ='Auto Print'!BF34 -> 1 | AZ17: ='Auto Print'!BI34 -> 1 | BC17: ='Auto Print'!BL34 -> 1 | BF17: ='Auto Print'!BO34 -> 1 | BI17: ='Auto Print'!BR34 -> 1 | BL17: ='Auto Print'!BU34 -> 1 | BO17: ='Auto Print'!BX34 -> 1 | BR17: ='Auto Print'!CA34 -> 1 | BU17: ='Auto Print'!CD34 -> 1 | BX17: ='Auto Print'!CG34 -> 1 | CA17: ='Auto Print'!CJ34 -> 1 | CD17: ='Auto Print'!CM34 -> 1 | CG17: ='Auto Print'!CP34 -> 1 | CJ17: ='Auto Print'!CS34 -> 1 | CM17: ='Auto Print'!CV34 -> 1 | CP17: ='Auto Print'!CY34 -> 1 | CS17: ='Auto Print'!DB34 -> 1 | CV17: ='Auto Print'!DE34 -> 1
G18: +/- | J18: =J17-J16 -> #REF! | M18: =M17-M16 -> 0 | P18: =P17-P16 -> 2796 | S18: =S17-S16 -> 4308 | V18: ='Auto Print'!Y35 -> 0.084663772 | Y18: ='Auto Print'!AB35 -> 0.56222261 | AB18: ='Auto Print'!AE35 -> -0.22254856 | AE18: ='Auto Print'!AH35 -> -0.19083855 | AH18: ='Auto Print'!AK35 -> 0.23089895 | AK18: ='Auto Print'!AN35 -> 1 | AN18: ='Auto Print'!AW35 -> 0.56904207 | AQ18: ='Auto Print'!AZ35 -> 0.89810953 | AT18: ='Auto Print'!BC35 -> -1.4617371 | AW18: ='Auto Print'!BF35 -> 0.62204828 | AZ18: ='Auto Print'!BI35 -> -0.08268066 | BC18: ='Auto Print'!BL35 -> -0.19121371 | BF18: ='Auto Print'!BO35 -> 0.10961649 | BI18: ='Auto Print'!BR35 -> -1.2810849 | BL18: ='Auto Print'!BU35 -> 0.26425713 | BO18: ='Auto Print'!BX35 -> 0.68290641 | BR18: ='Auto Print'!CA35 -> 0.70407261 | BU18: ='Auto Print'!CD35 -> 0.58157888 | BX18: ='Auto Print'!CG35 -> -0.17706695 | CA18: ='Auto Print'!CJ35 -> -0.25230396 | CD18: ='Auto Print'!CM35 -> -0.03260151 | CG18: ='Auto Print'!CP35 -> -0.03260151 | CJ18: ='Auto Print'!CS35 -> 0.11473509 | CM18: ='Auto Print'!CV35 -> -0.93587429 | CP18: ='Auto Print'!CY35 -> -0.93587429 | CS18: ='Auto Print'!DB35 -> -1.3477624 | CV18: ='Auto Print'!DE35 -> -0.27437354
G19: TOTAL BALANCE | V19: =SUM(V15) -> 33935 | Y19: =SUM(Y15:AM15) -> 130585 | AB19: =SUM(AB15:AP15) -> 129933 | AN19: =SUM(AN15:AY15) -> 94836 | AQ19: =SUM(AQ15:BB15) -> 113139 | AZ19: =SUM(AZ15:BK15) -> 145480.8 | BC19: =SUM(BC15:BN15) -> 130608 | BL19: =SUM(BL15:BZ15) -> 77644.2 | BO19: =SUM(BO15:CC15) -> 88758 | CA19: =SUM(CA15:CL15) -> 107575.5 | CD19: =SUM(CD15:CO15) -> 135108 | CM19: =SUM(CM15:CX15) -> 204205.5 | CP19: =SUM(CP15:DA15) -> 148812
V22: SEPT | Y22: OCTOBER | AN22: NOVEMBER | AZ22: DECEMBER | BL22: JANUARY | CA22: FEBRUARY | CM22: MARCH
J23: =+#REF! -> #REF! | M23: ='Auto Print'!P31 -> WEEK PRODUKSI 37 | P23: ='Auto Print'!S31 -> WEEK PRODUKSI 38 | S23: ='Auto Print'!V31 -> WEEK PRODUKSI 39 | V23: W39 | Y23: W40 | AB23: W41 | AE23: W42 | AH23: W43 | AK23: W44 | AN23: W45 | AQ23: W46 | AT23: W47 | AW23: W48 | AZ23: W49 | BC23: W50 | BF23: W51 | BI23: W52 | BL23: W1 | BO23: W2 | BR23: W3 | BU23: W4 | BX23: W5 | CA23: W6 | CD23: W7 | CG23: W8 | CJ23: W9 | CM23: W10 | CP23: W11 | CS23: W12 | CV23: W13
C24: TOTAL MESIN | D24: 2 | G24: BALANCE/WEEK | J24: =K9 -> 0 | M24: ='Auto Print'!P32 -> 0 | P24: ='Auto Print'!S32 -> 7575 | S24: ='Auto Print'!V32 -> 22052 | V24: ='Auto Print'!Y70 -> 33935 | Y24: ='Auto Print'!AB70 -> 13969 | AB24: ='Auto Print'!AE70 -> 46578 | AE24: ='Auto Print'!AH70 -> 43824 | AH24: ='Auto Print'!AK70 -> 26214 | AK24: ='Auto Print'!AN70 -> 0 | AN24: ='Auto Print'!AW70 -> 13317 | AQ24: ='Auto Print'!AZ70 -> 2715 | AT24: ='Auto Print'!BC70 -> 68733 | AW24: ='Auto Print'!BF70 -> 10071 | AZ24: ='Auto Print'!BI70 -> 31620 | BC24: ='Auto Print'!BL70 -> 34512 | BF24: ='Auto Print'!BO70 -> 26496 | BI24: ='Auto Print'!BR70 -> 52852.8 | BL24: ='Auto Print'!BU70 -> 16747.2 | BO24: ='Auto Print'!BX70 -> 9031.2 | BR24: ='Auto Print'!CA70 -> 8467.2 | BU24: ='Auto Print'!CD70 -> 11731.2 | BX24: ='Auto Print'!CG70 -> 31667.4 | CA24: ='Auto Print'!CJ70 -> 27861 | CD24: ='Auto Print'!CM70 -> 27861 | CG24: ='Auto Print'!CP70 -> 27861 | CJ24: ='Auto Print'!CS70 -> 23992.5 | CM24: ='Auto Print'!CV70 -> 55393.5 | CP24: ='Auto Print'!CY70 -> 55393.5 | CS24: ='Auto Print'!DB70 -> 55393.5 | CV24: ='Auto Print'!DE70 -> 38025
A25: AUTO CUTTING | C25: ADD | D25: 0 | G25: KEBUTUHAN MESIN | J25: =L9 -> 0 | M25: ='Auto Print'!P33 -> 0 | P25: ='Auto Print'!S33 -> 0 | S25: ='Auto Print'!V33 -> 0.61674332 | V25: ='Auto Print'!Y71 -> 0.69238283 | Y25: ='Auto Print'!AB71 -> 0.28558506 | AB25: ='Auto Print'!AE71 -> 1.0236499 | AE25: ='Auto Print'!AH71 -> 0.92664426 | AH25: ='Auto Print'!AK71 -> 0.5630016 | AK25: ='Auto Print'!AN71 -> 0 | AN25: ='Auto Print'!AW71 -> 0.24737903 | AQ25: ='Auto Print'!AZ71 -> 0.050434336 | AT25: ='Auto Print'!BC71 -> 1.2767968 | AW25: ='Auto Print'!BF71 -> 0.18708074 | AZ25: ='Auto Print'!BI71 -> 0.5873789 | BC25: ='Auto Print'!BL71 -> 0.64110122 | BF25: ='Auto Print'!BO71 -> 0.49219454 | BI25: ='Auto Print'!BR71 -> 1.3628659 | BL25: ='Auto Print'!BU71 -> 0.54945862 | BO25: ='Auto Print'!BX71 -> 0.30972854 | BR25: ='Auto Print'!CA71 -> 0.29925158 | BU25: ='Auto Print'!CD71 -> 0.35988424 | BX25: ='Auto Print'!CG71 -> 1.8114317 | CA25: ='Auto Print'!CJ71 -> 2.11109 | CD25: ='Auto Print'!CM71 -> 1.7407233 | CG25: ='Auto Print'!CP71 -> 1.7407233 | CJ25: ='Auto Print'!CS71 -> 1.4460501 | CM25: ='Auto Print'!CV71 -> 2.0293609 | CP25: ='Auto Print'!CY71 -> 2.0293609 | CS25: ='Auto Print'!DB71 -> 2.4611398 | CV25: ='Auto Print'!DE71 -> 0.70635935
C26: TOTAL | D26: 2 | G26: KAPASITAS MESIN | J26: =+$D$58 -> 0 | M26: ='Auto Print'!P34 -> 1 | P26: ='Auto Print'!S34 -> 1 | S26: ='Auto Print'!V34 -> 1 | V26: ='Auto Print'!Y72 -> 2 | Y26: ='Auto Print'!AB72 -> 2 | AB26: ='Auto Print'!AE72 -> 2 | AE26: ='Auto Print'!AH72 -> 2 | AH26: ='Auto Print'!AK72 -> 2 | AK26: ='Auto Print'!AN72 -> 2 | AN26: ='Auto Print'!AW72 -> 2 | AQ26: ='Auto Print'!AZ72 -> 2 | AT26: ='Auto Print'!BC72 -> 2 | AW26: ='Auto Print'!BF72 -> 2 | AZ26: ='Auto Print'!BI72 -> 2 | BC26: ='Auto Print'!BL72 -> 2 | BF26: ='Auto Print'!BO72 -> 2 | BI26: ='Auto Print'!BR72 -> 2 | BL26: ='Auto Print'!BU72 -> 2 | BO26: ='Auto Print'!BX72 -> 2 | BR26: ='Auto Print'!CA72 -> 2 | BU26: ='Auto Print'!CD72 -> 2 | BX26: ='Auto Print'!CG72 -> 2 | CA26: ='Auto Print'!CJ72 -> 2 | CD26: ='Auto Print'!CM72 -> 2 | CG26: ='Auto Print'!CP72 -> 2 | CJ26: ='Auto Print'!CS72 -> 2 | CM26: ='Auto Print'!CV72 -> 2 | CP26: ='Auto Print'!CY72 -> 2 | CS26: ='Auto Print'!DB72 -> 2 | CV26: ='Auto Print'!DE72 -> 2
G27: +/- | J27: =J26-J25 -> 0 | M27: =M26-M25 -> 1 | P27: =P26-P25 -> 1 | S27: =S26-S25 -> 0.38325668 | V27: ='Auto Print'!Y73 -> 1.3076172 | Y27: ='Auto Print'!AB73 -> 1.7144149 | AB27: ='Auto Print'!AE73 -> 0.97635009 | AE27: ='Auto Print'!AH73 -> 1.0733557 | AH27: ='Auto Print'!AK73 -> 1.4369984 | AK27: ='Auto Print'!AN73 -> 2 | AN27: ='Auto Print'!AW73 -> 1.752621 | AQ27: ='Auto Print'!AZ73 -> 1.9495657 | AT27: ='Auto Print'!BC73 -> 0.72320323 | AW27: ='Auto Print'!BF73 -> 1.8129193 | AZ27: ='Auto Print'!BI73 -> 1.4126211 | BC27: ='Auto Print'!BL73 -> 1.3588988 | BF27: ='Auto Print'!BO73 -> 1.5078055 | BI27: ='Auto Print'!BR73 -> 0.63713413 | BL27: ='Auto Print'!BU73 -> 1.4505414 | BO27: ='Auto Print'!BX73 -> 1.6902715 | BR27: ='Auto Print'!CA73 -> 1.7007484 | BU27: ='Auto Print'!CD73 -> 1.6401158 | BX27: ='Auto Print'!CG73 -> 0.18856829 | CA27: ='Auto Print'!CJ73 -> -0.11108999 | CD27: ='Auto Print'!CM73 -> 0.25927667 | CG27: ='Auto Print'!CP73 -> 0.25927667 | CJ27: ='Auto Print'!CS73 -> 0.55394986 | CM27: ='Auto Print'!CV73 -> -0.02936085 | CP27: ='Auto Print'!CY73 -> -0.02936085 | CS27: ='Auto Print'!DB73 -> -0.46113975 | CV27: ='Auto Print'!DE73 -> 1.2936407
G28: TOTAL BALANCE | V28: =SUM(V24) -> 33935 | Y28: =SUM(Y24:AM24) -> 130585 | AB28: =SUM(AB24:AP24) -> 129933 | AN28: =SUM(AN24:AY24) -> 94836 | AQ28: =SUM(AQ24:BB24) -> 113139 | AZ28: =SUM(AZ24:BK24) -> 145480.8 | BC28: =SUM(BC24:BN24) -> 130608 | BL28: =SUM(BL24:BZ24) -> 77644.2 | BO28: =SUM(BO24:CC24) -> 88758 | CA28: =SUM(CA24:CL24) -> 107575.5 | CD28: =SUM(CD24:CO24) -> 135108 | CM28: =SUM(CM24:CX24) -> 204205.5 | CP28: =SUM(CP24:DA24) -> 148812
V31: SEPT | Y31: OCTOBER | AN31: NOVEMBER | AZ31: DECEMBER | BL31: JANUARY | CA31: FEBRUARY | CM31: MARCH
J32: =+#REF! -> #REF! | M32: =Emboss!P61 -> WEEK PRODUKSI 37 | P32: =Emboss!S61 -> WEEK PRODUKSI 38 | S32: =Emboss!V61 -> WEEK PRODUKSI 39 | V32: W39 | Y32: W40 | AB32: W41 | AE32: W42 | AH32: W43 | AK32: W44 | AN32: W45 | AQ32: W46 | AT32: W47 | AW32: W48 | AZ32: W49 | BC32: W50 | BF32: W51 | BI32: W52 | BL32: W1 | BO32: W2 | BR32: W3 | BU32: W4 | BX32: W5 | CA32: W6 | CD32: W7 | CG32: W8 | CJ32: W9 | CM32: W10 | CP32: W11 | CS32: W12 | CV32: W13
G33: BALANCE/WEEK | J33: =K$89 -> 0 | M33: =Emboss!P62 -> 702 | P33: =Emboss!S62 -> 14086 | S33: =Emboss!V62 -> 90290 | V33: =Emboss!Y62 -> 106700 | Y33: =Emboss!AB62 -> 90332 | AB33: =Emboss!AE62 -> 165918 | AE33: =Emboss!AH62 -> 128246 | AH33: =Emboss!AK62 -> 140064 | AK33: =Emboss!AN62 -> 32490 | AN33: =Emboss!AQ62 -> 19800 | AQ33: =Emboss!AZ62 -> 53817 | AT33: =Emboss!BC62 -> 6813 | AW33: =Emboss!BF62 -> 34017 | AZ33: =Emboss!BR62 -> 74365.5 | BC33: =Emboss!BU62 -> 83155.5 | BF33: =Emboss!BX62 -> 63523.5 | BI33: =Emboss!CA62 -> 117162.7 | BL33: =Emboss!CD62 -> 40788.4 | BO33: =Emboss!CG62 -> 25356.4 | BR33: =Emboss!CJ62 -> 24228.4 | BU33: =Emboss!CM62 -> 30756.4 | BX33: =Emboss!CP62 -> 87278.2 | CA33: =Emboss!CS62 -> 81371.5 | CD33: =Emboss!CV62 -> 84143.5 | CG33: =Emboss!CY62 -> 79643.5 | CJ33: =Emboss!DB62 -> 64305 | CM33: =Emboss!DE62 -> 127072.5 | CP33: =Emboss!DH62 -> 127072.5 | CS33: =Emboss!DK62 -> 127072.5 | CV33: =Emboss!DN62 -> 82362
A34: EMBOSS | C34: TOTAL MESIN | D34: 22 | G34: KEBUTUHAN MESIN | J34: =L$89 -> 0 | M34: =Emboss!P63 -> 0 | P34: =Emboss!S63 -> 0 | S34: =Emboss!V63 -> 12.53807 | V34: =Emboss!Y63 -> 14.856964 | Y34: =Emboss!AB63 -> 12.573359 | AB34: =Emboss!AE63 -> 22.851502 | AE34: =Emboss!AH63 -> 18.815962 | AH34: =Emboss!AK63 -> 23.066017 | AK34: =Emboss!AN63 -> 5.5423561 | AN34: =Emboss!AQ63 -> 3.1634615 | AQ34: =Emboss!AZ63 -> 7.8921471 | AT34: =Emboss!BC63 -> 0.85124133 | AW34: =Emboss!BF63 -> 4.7286856 | AZ34: =Emboss!BR63 -> 9.6180265 | BC34: =Emboss!BU63 -> 10.805826 | BF34: =Emboss!BX63 -> 8.23278 | BI34: =Emboss!CA63 -> 17.824679 | BL34: =Emboss!CD63 -> 5.7193179 | BO34: =Emboss!CG63 -> 2.7294257 | BR34: =Emboss!CJ63 -> 2.5868895 | BU34: =Emboss!CM63 -> 3.4117797 | BX34: =Emboss!CP63 -> 6.4781612 | CA34: =Emboss!CS63 -> 7.1073466 | CD34: =Emboss!CV63 -> 6.2579864 | CG34: =Emboss!CY63 -> 5.5390179 | CJ34: =Emboss!DB63 -> 5.4411131 | CM34: =Emboss!DE63 -> 13.882038 | CP34: =Emboss!DH63 -> 13.882038 | CS34: =Emboss!DK63 -> 16.966936 | CV34: =Emboss!DN63 -> 10.894759
C35: ADD 01/12 | D35: 10 | G35: KAPASITAS MESIN | J35: 22 | M35: =Emboss!P64 -> 22 | P35: =Emboss!S64 -> 22 | S35: =Emboss!V64 -> 22 | V35: =Emboss!Y64 -> 22 | Y35: =Emboss!AB64 -> 22 | AB35: =Emboss!AE64 -> 22 | AE35: =Emboss!AH64 -> 22 | AH35: =Emboss!AK64 -> 22 | AK35: =Emboss!AN64 -> 22 | AN35: =Emboss!AQ64 -> 22 | AQ35: =Emboss!AZ64 -> 22 | AT35: =Emboss!BC64 -> 22 | AW35: =Emboss!BF64 -> 22 | AZ35: =Emboss!BR64 -> 32 | BC35: =Emboss!BU64 -> 32 | BF35: =Emboss!BX64 -> 32 | BI35: =Emboss!CA64 -> 32 | BL35: =Emboss!CD64 -> 32 | BO35: =Emboss!CG64 -> 32 | BR35: =Emboss!CJ64 -> 32 | BU35: =Emboss!CM64 -> 32 | BX35: =Emboss!CP64 -> 32 | CA35: =Emboss!CS64 -> 32 | CD35: =Emboss!CV64 -> 32 | CG35: =Emboss!CY64 -> 32 | CJ35: =Emboss!DB64 -> 32 | CM35: =Emboss!DE64 -> 32 | CP35: =Emboss!DH64 -> 32 | CS35: =Emboss!DK64 -> 32 | CV35: =Emboss!DN64 -> 32
C36: TOTAL MESIN | D36: =SUM(D34:D35) -> 32 | G36: +/- | J36: =J35-J34 -> 22 | M36: =Emboss!P65 -> 22 | P36: =Emboss!S65 -> 22 | S36: =Emboss!V65 -> 9.46193 | V36: =Emboss!Y65 -> 7.1430359 | Y36: =Emboss!AB65 -> 9.4266414 | AB36: =Emboss!AE65 -> -0.851502 | AE36: =Emboss!AH65 -> 3.1840382 | AH36: =Emboss!AK65 -> -1.0660166 | AK36: =Emboss!AN65 -> 16.457644 | AN36: =Emboss!AQ65 -> 18.836538 | AQ36: =Emboss!AZ65 -> 14.107853 | AT36: =Emboss!BC65 -> 21.148759 | AW36: =Emboss!BF65 -> 17.271314 | AZ36: =Emboss!BR65 -> 22.381974 | BC36: =Emboss!BU65 -> 21.194174 | BF36: =Emboss!BX65 -> 23.76722 | BI36: =Emboss!CA65 -> 14.175321 | BL36: =Emboss!CD65 -> 26.280682 | BO36: =Emboss!CG65 -> 29.270574 | BR36: =Emboss!CJ65 -> 29.413111 | BU36: =Emboss!CM65 -> 28.58822 | BX36: =Emboss!CP65 -> 25.521839 | CA36: =Emboss!CS65 -> 24.892653 | CD36: =Emboss!CV65 -> 25.742014 | CG36: =Emboss!CY65 -> 26.460982 | CJ36: =Emboss!DB65 -> 26.558887 | CM36: =Emboss!DE65 -> 18.117962 | CP36: =Emboss!DH65 -> 18.117962 | CS36: =Emboss!DK65 -> 15.033064 | CV36: =Emboss!DN65 -> 21.105241
G37: TOTAL BALANCE | V37: =SUM(V33) -> 106700 | Y37: =SUM(Y33:AM33) -> 557050 | AB37: =SUM(AB33:AP33) -> 486518 | AN37: =SUM(AN33:AY33) -> 114447 | AQ37: =SUM(AQ33:BB33) -> 169012.5 | AZ37: =SUM(AZ33:BK33) -> 338207.2 | BC37: =SUM(BC33:BN33) -> 304630.1 | BL37: =SUM(BL33:BZ33) -> 208407.8 | BO37: =SUM(BO33:CC33) -> 248990.9 | CA37: =SUM(CA33:CL33) -> 309463.5 | CD37: =SUM(CD33:CO33) -> 355164.5 | CM37: =SUM(CM33:CX33) -> 463579.5 | CP37: =SUM(CP33:DA33) -> 336507
V40: SEPT | Y40: OCTOBER | AN40: NOVEMBER | AZ40: DECEMBER | BL40: JANUARY | CA40: FEBRUARY | CM40: MARCH
J41: =+#REF! -> #REF! | M41: ='Cut Press'!P32 -> WEEK PRODUKSI 37 | P41: ='Cut Press'!S32 -> WEEK PRODUKSI 38 | S41: ='Cut Press'!V32 -> WEEK PRODUKSI 39 | V41: W39 | Y41: W40 | AB41: W41 | AE41: W42 | AH41: W43 | AK41: W44 | AN41: W45 | AQ41: W46 | AT41: W47 | AW41: W48 | AZ41: W49 | BC41: W50 | BF41: W51 | BI41: W52 | BL41: W1 | BO41: W2 | BR41: W3 | BU41: W4 | BX41: W5 | CA41: W6 | CD41: W7 | CG41: W8 | CJ41: W9 | CM41: W10 | CP41: W11 | CS41: W12 | CV41: W13
G42: BALANCE/WEEK | J42: =K$62 -> 0 | M42: ='Cut Press'!P34 -> 0 | P42: ='Cut Press'!S34 -> 9462 | S42: ='Cut Press'!V34 -> 12324 | V42: ='Cut Press'!Y34 -> 21786 | Y42: ='Cut Press'!AB34 -> 36030 | AB42: ='Cut Press'!AE34 -> 68376 | AE42: ='Cut Press'!AH34 -> 55860 | AH42: ='Cut Press'!AK34 -> 24456 | AK42: ='Cut Press'!AN34 -> 1362 | AN42: ='Cut Press'!AW34 -> 32293.5 | AQ42: ='Cut Press'!BC34 -> 4072.5 | AT42: ='Cut Press'!BF34 -> 110947.5 | AW42: ='Cut Press'!BI34 -> 26380.5 | AZ42: ='Cut Press'!BL34 -> 56629.5 | BC42: ='Cut Press'!BO34 -> 59863.5 | BF42: ='Cut Press'!BR34 -> 44239.5 | BI42: ='Cut Press'!BU34 -> 80077.5 | BL42: ='Cut Press'!BX34 -> 25533.6 | BO42: ='Cut Press'!CA34 -> 9849.6 | BR42: ='Cut Press'!CD34 -> 9003.6 | BU42: ='Cut Press'!CG34 -> 13899.6 | BX42: ='Cut Press'!CJ34 -> 15645.6 | CA42: ='Cut Press'!CM34 -> 10498.5 | CD42: ='Cut Press'!CP34 -> 10960.5 | CG42: ='Cut Press'!CS34 -> 10210.5 | CJ42: ='Cut Press'!CV34 -> 10210.5 | CM42: ='Cut Press'!CY34 -> 63454.5 | CP42: ='Cut Press'!DB34 -> 63454.5 | CS42: ='Cut Press'!DE34 -> 63454.5 | CV42: ='Cut Press'!DH34 -> 63454.5
A43: CUTTING PRESS | C43: 2 M/C | D43: 16 | G43: KEBUTUHAN HOLD | J43: =L$62 -> 0 | M43: ='Cut Press'!P35 -> 0 | P43: ='Cut Press'!S35 -> 0 | S43: ='Cut Press'!V35 -> 2.7151515 | V43: ='Cut Press'!Y35 -> 4.8796537 | Y43: ='Cut Press'!AB35 -> 8.5044733 | AB43: ='Cut Press'!AE35 -> 18.077922 | AE43: ='Cut Press'!AH35 -> 12.335931 | AH43: ='Cut Press'!AK35 -> 6.3792208 | AK43: ='Cut Press'!AN35 -> 0.78614719 | AN43: ='Cut Press'!AW35 -> 7.4831169 | AQ43: ='Cut Press'!BC35 -> 0.78354978 | AT43: ='Cut Press'!BF35 -> 21.921212 | AW43: ='Cut Press'!BI35 -> 0.74563492 | AZ43: ='Cut Press'!BL35 -> 10.37104 | BC43: ='Cut Press'!BO35 -> 11.517749 | BF43: ='Cut Press'!BR35 -> 8.5116883 | BI43: ='Cut Press'!BU35 -> 15.406926 | BL43: ='Cut Press'!BX35 -> 17.169524 | BO43: ='Cut Press'!CA35 -> 1.8950649 | BR43: ='Cut Press'!CD35 -> 1.7322944 | BU43: ='Cut Press'!CG35 -> 2.6742857 | BX43: ='Cut Press'!CJ35 -> 3.6791534 | CA43: ='Cut Press'!CM35 -> 2.6042328 | CD43: ='Cut Press'!CP35 -> 2.3974026 | CG43: ='Cut Press'!CS35 -> 1.9645022 | CJ43: ='Cut Press'!CV35 -> 1.9645022 | CM43: ='Cut Press'!CY35 -> 12.208658 | CP43: ='Cut Press'!DB35 -> 12.208658 | CS43: ='Cut Press'!DE35 -> 14.921693 | CV43: ='Cut Press'!DH35 -> 12.208658
A44: (Model 880,1906) | C44: ADD (2 MC) | D44: 16 | G44: KAPASITAS HOLD | J44: 8 | M44: ='Cut Press'!P36 -> 8 | P44: ='Cut Press'!S36 -> 8 | S44: ='Cut Press'!V36 -> 8 | V44: ='Cut Press'!Y36 -> 16 | Y44: ='Cut Press'!AB36 -> 16 | AB44: ='Cut Press'!AE36 -> 16 | AE44: ='Cut Press'!AH36 -> 16 | AH44: ='Cut Press'!AK36 -> 16 | AK44: ='Cut Press'!AN36 -> 16 | AN44: ='Cut Press'!AW36 -> 16 | AQ44: ='Cut Press'!BC36 -> 16 | AT44: ='Cut Press'!BF36 -> 16 | AW44: ='Cut Press'!BI36 -> 16 | AZ44: ='Cut Press'!BL36 -> 16 | BC44: ='Cut Press'!BO36 -> 16 | BF44: ='Cut Press'!BR36 -> 16 | BI44: ='Cut Press'!BU36 -> 16 | BL44: ='Cut Press'!BX36 -> 16 | BO44: ='Cut Press'!CA36 -> 16 | BR44: ='Cut Press'!CD36 -> 16 | BU44: ='Cut Press'!CG36 -> 16 | BX44: ='Cut Press'!CJ36 -> 16 | CA44: ='Cut Press'!CM36 -> 16 | CD44: ='Cut Press'!CP36 -> 16 | CG44: ='Cut Press'!CS36 -> 16 | CJ44: ='Cut Press'!CV36 -> 16 | CM44: ='Cut Press'!CY36 -> 16 | CP44: ='Cut Press'!DB36 -> 16 | CS44: ='Cut Press'!DE36 -> 16 | CV44: ='Cut Press'!DH36 -> 16
G45: +/- | J45: =J44-J43 -> 8 | M45: ='Cut Press'!P37 -> 8 | P45: ='Cut Press'!S37 -> 8 | S45: ='Cut Press'!V37 -> 5.2848485 | V45: ='Cut Press'!Y37 -> 11.120346 | Y45: ='Cut Press'!AB37 -> 7.4955267 | AB45: ='Cut Press'!AE37 -> -2.0779221 | AE45: ='Cut Press'!AH37 -> 3.6640693 | AH45: ='Cut Press'!AK37 -> 9.6207792 | AK45: ='Cut Press'!AN37 -> 15.213853 | AN45: ='Cut Press'!AW37 -> 8.5168831 | AQ45: ='Cut Press'!BC37 -> 15.21645 | AT45: ='Cut Press'!BF37 -> -5.9212121 | AW45: ='Cut Press'!BI37 -> 15.254365 | AZ45: ='Cut Press'!BL37 -> 5.6289602 | BC45: ='Cut Press'!BO37 -> 4.4822511 | BF45: ='Cut Press'!BR37 -> 7.4883117 | BI45: ='Cut Press'!BU37 -> 0.59307359 | BL45: ='Cut Press'!BX37 -> -1.1695238 | BO45: ='Cut Press'!CA37 -> 14.104935 | BR45: ='Cut Press'!CD37 -> 14.267706 | BU45: ='Cut Press'!CG37 -> 13.325714 | BX45: ='Cut Press'!CJ37 -> 12.320847 | CA45: ='Cut Press'!CM37 -> 13.395767 | CD45: ='Cut Press'!CP37 -> 13.602597 | CG45: ='Cut Press'!CS37 -> 14.035498 | CJ45: ='Cut Press'!CV37 -> 14.035498 | CM45: ='Cut Press'!CY37 -> 3.791342 | CP45: ='Cut Press'!DB37 -> 3.791342 | CS45: ='Cut Press'!DE37 -> 1.0783069 | CV45: ='Cut Press'!DH37 -> 3.791342
